Workbook

Sheet Summary
A1: Lumhe Instagram campaign: blog watercolour images
A2: 200 posts, two per day, from 7 Oct 2026 to 14 Jan 2027. Every Indian and US/UK festival in the window has a post about 10 days before, a reminder 1-2 days before (same images, different copy) and a greeting on the day. All visuals are raw watercolour illustrations with no title text on them. Apart from the intentional festival reminder that reuses its first post's images, no image is used twice.
A4: By format
A5: Single | B5: =COUNTIF(Calendar!$F$2:$F$201,"Single") -> 103
A6: Carousel | B6: =COUNTIF(Calendar!$F$2:$F$201,"Carousel") -> 69
A7: Reel | B7: =COUNTIF(Calendar!$F$2:$F$201,"Reel") -> 28
A8: Total posts | B8: =SUM(B5:B7) -> 200
A10: By market × format | B10: Single | C10: Carousel | D10: Reel | E10: Total
A11: India | B11: =COUNTIFS(Calendar!$G$2:$G$201,"India",Calendar!$F$2:$F$201,"Single") -> 32 | C11: =COUNTIFS(Calendar!$G$2:$G$201,"India",Calendar!$F$2:$F$201,"Carousel") -> 31 | D11: =COUNTIFS(Calendar!$G$2:$G$201,"India",Calendar!$F$2:$F$201,"Reel") -> 13 | E11: =SUM(B11:D11) -> 76
A12: USA | B12: =COUNTIFS(Calendar!$G$2:$G$201,"USA",Calendar!$F$2:$F$201,"Single") -> 32 | C12: =COUNTIFS(Calendar!$G$2:$G$201,"USA",Calendar!$F$2:$F$201,"Carousel") -> 19 | D12: =COUNTIFS(Calendar!$G$2:$G$201,"USA",Calendar!$F$2:$F$201,"Reel") -> 6 | E12: =SUM(B12:D12) -> 57
A13: UK | B13: =COUNTIFS(Calendar!$G$2:$G$201,"UK",Calendar!$F$2:$F$201,"Single") -> 32 | C13: =COUNTIFS(Calendar!$G$2:$G$201,"UK",Calendar!$F$2:$F$201,"Carousel") -> 10 | D13: =COUNTIFS(Calendar!$G$2:$G$201,"UK",Calendar!$F$2:$F$201,"Reel") -> 2 | E13: =SUM(B13:D13) -> 44
A14: Global | B14: =COUNTIFS(Calendar!$G$2:$G$201,"Global",Calendar!$F$2:$F$201,"Single") -> 7 | C14: =COUNTIFS(Calendar!$G$2:$G$201,"Global",Calendar!$F$2:$F$201,"Carousel") -> 9 | D14: =COUNTIFS(Calendar!$G$2:$G$201,"Global",Calendar!$F$2:$F$201,"Reel") -> 7 | E14: =SUM(B14:D14) -> 23
A16: Workflow status
A17: Ready | B17: =COUNTIF(Calendar!$V$2:$V$201,"Ready") -> 200
A18: Scheduled | B18: =COUNTIF(Calendar!$V$2:$V$201,"Scheduled") -> 0
A19: Posted | B19: =COUNTIF(Calendar!$V$2:$V$201,"Posted") -> 0
A20: On hold | B20: =COUNTIF(Calendar!$V$2:$V$201,"On hold") -> 0
A22: Images
A23: Watercolour images logged | B23: =COUNTA('Image usage log'!A2:A264) -> 263
A24: Used in at least one post | B24: =COUNTIF('Image usage log'!D2:D264,"Used") -> 245
A25: Skipped as duplicate artwork | B25: =COUNTIF('Image usage log'!D2:D264,"Skipped (duplicate)") -> 18
A27: How to use
A28: • Calendar tab: one row per post, with the caption, hashtags, first comment, alt text and file names. Change the Status column as you go (Ready, Scheduled, Posted, On hold).
A29: • Asset folder: every post has its own folder under Posts/, and the folders are numbered in posting order. Each folder holds the ready-to-upload JPG or MP4 files plus caption.txt.
A30: • Reels have no audio. Add a trending sound in Instagram using the "Audio suggestion" column. reel_cover.jpg is the suggested cover frame.
A31: • Post times: two slots a day, set by market. India 12:30 and 19:00 IST, US 19:30 and 21:30 IST (9:00 and 11:00 AM ET), UK 16:30 and 23:00 IST, Global 13:00 and 20:30 IST. Times assume one shared Instagram account.
A32: • Festival dates: see the Festival coverage tab. Please check Navratri, Dussehra, Karva Chauth, Dhanteras, Diwali, Chhath, Dev Uthani Ekadashi, Guru Nanak Jayanti, Lohri and Sankranti against your panchang, and Thanksgiving, Hanukkah and Bonfire Night against a calendar, before scheduling.
A33: • Lumhe facts in the copy come from the Lumhe feature pages: per-function RSVP, Moments, Digital Lifafa (India only, by UPI) and Upload Any Invite. No statistics or testimonials were invented.

Sheet Calendar
A1: # | B1: Date | C1: Day | D1: Time (IST) | E1: Target local time | F1: Format | G1: Market | H1: Post ID | I1: Title | J1: On-image hook | K1: Caption | L1: Hashtags | M1: First comment | N1: Alt text | O1: CTA on visual | P1: Slides / length | Q1: Audio suggestion | R1: Images used | S1: Source blog(s) | T1: Asset folder | U1: Files | V1: Status | W1: Posted link / notes | X1: Festival | Y1: Festival date | Z1: Role | AA1: Linked post (same images)
A2: 1 | B2: 46302 | C2: =TEXT(B2,"ddd") -> Wed | D2: 12:30 | E2: IST | F2: Single | G2: India | H2: E03 | I2: Telugu shubhalekha closing line | J2: Sakutumba saparivaara sametamga vichchesi, vadhuvarulanu aashirvadinchandi. | K2: Turmeric on the corners, and one line elders always read twice. A Telugu pelli patrika (శుభలేఖ) usually opens with Sri Ganeshaya Namah, names both families, gives the muhurtham, and closes by asking guests to come with family and bless the couple. That closing line is the heart of it. Sending to cousins abroad too? Keep the Telugu line, then add a simple English one below it so everyone feels invited. 💛 Upload your shubhalekha to Lumhe and share one link for Pellikuthuru, the muhurtham and the reception. Link in bio. | L2: #Lumhe #TeluguWedding #Shubhalekha #PelliPatrika #TeluguPelli #TeluguWeddingCard #Muhurtham #HyderabadWeddings #VizagWeddings #SouthIndianWedding #WeddingCardIdeas #TeluguAmmayi | M2: Does your family still put pasupu and kumkum on the card corners? Tell us below. | N2: Watercolour of a turmeric-dabbed wedding card on a brass plate with yellow talambralu rice, mango leaves and marigolds. Text: the Telugu closing line 'Sakutumba saparivaara sametamga vichchesi, vadhuvarulanu aashirvadinchandi' with its English meaning. | O2: Upload your shubhalekha | P2: 1 image · 4:5 | R2: EV-E03_A | S2: New watercolour, blog topic: telugu | T2: Posts/001_2026-10-07_Single_E03_Telugu-shubhalekha-closing-line | U2: post.jpg | V2: Ready | Z2: Evergreen
A3: 2 | B3: 46302 | C3: =TEXT(B3,"ddd") -> Wed | D3: 19:00 | E3: IST | F3: Carousel | G3: India | H3: F01 | I3: Navratri hosting and invite guide | J3: Nine nights, one invite link | K3: Navratri starts Sunday. Your society Garba planning starts now. 💃 Ten days is enough time to do this without panic: send the invite, lock the dhol, count the dandiya sticks and know how many kanyas are coming for Ashtami. Swipe for: • Garba night invite wording you can copy • A Kanya Pujan message for parents • The host checklist to book this week • A simple way to use the nine colours Hosting more than one night? Create one Lumhe event and add each night as its own function. Guests RSVP only for the nights they can make, you get a live headcount, and the photos stay together in Moments instead of fifty WhatsApp chats. Save this, then create your Navratri invite free. Link in bio. | L3: #Lumhe #Navratri2026 #SharadNavratri #Garba #DandiyaNight #GarbaNight #NavratriVibes #KanyaPujan #ChaniyaCholi #SocietyGarba #NavratriCelebration #FestiveSeason | M3: Team Garba or team Dandiya? Tell us how your society celebrates. | N3: Watercolour carousel: a couple in mirror-work outfits twirling with dandiya sticks beside a lamp-lit garbo pot and marigolds, and a close-up of a puja thali with a diya, coconut and dandiya sticks. Slides share Navratri invite wording and a host checklist. | O3: Create your invite free | P3: 6 slides | R3: PAIR-NAV_A, PAIR-NAV_B | S3: New watercolour, blog topic: festival | New watercolour, blog topic: festival | T3: Posts/002_2026-10-07_Carousel_F01_Navratri-hosting-and-invite-guide | U3: slide_01.jpg, slide_02.jpg, slide_03.jpg, slide_04.jpg, slide_05.jpg, slide_06.jpg | V3: Ready | X3: Sharad Navratri | Y3: 2026-10-11 | Z3: 10 days before | AA3: F02
A4: 3 | B4: 46303 | C4: =TEXT(B4,"ddd") -> Thu | D4: 12:30 | E4: IST | F4: Carousel | G4: India | H4: E01 | I4: Bengali biyer card wording guide | J4: Bengali wording, from Prajapataye to Bou Bhaat | K4: Prajapati on the card, and a guest list longer than the menu. A Bengali biyer card does a lot of work. It comes from the parents, names every ceremony from Ashirbaad to Bou Bhaat, and speaks to elders and friends in slightly different voices. Swipe for: • What to put at the very top • A classic Bengali closing line, with meaning • An English version from the bride's parents • Why Bou Bhaat often needs its own invite Tip: print one bilingual card for the family, then send the same card digitally to everyone who lives far away. Save this for the evening Mama, Mashi and Baba sit down to finalise the card. Then upload it to Lumhe and share one link with a separate RSVP for each function. Link in bio. | L4: #Lumhe #BengaliWedding #BiyerCard #BengaliBride #BongWedding #ShubhoBibaho #BouBhaat #GayeHolud #KolkataWeddings #WeddingCardWording #BengaliCulture #WeddingInvitationIndia #DigitalWeddingCard | M4: Which ceremony is your favourite: Gaye Holud, Shubho Drishti or Bou Bhaat? | N4: Watercolour carousel: a Bengali bride in a red Banarasi and shola crown holding betel leaves before her face, and a red-and-white card with a butterfly motif beside conch-shell bangles and marigolds. Slides share Bengali and English invitation wording. | O4: Share your biyer card | P4: 6 slides | R4: EV-E01_A, EV-E01_B | S4: New watercolour, blog topic: bengali-wedding-invitation | New watercolour, blog topic: bengali-wedding-invitation | T4: Posts/003_2026-10-08_Carousel_E01_Bengali-biyer-card-wording-guide | U4: slide_01.jpg, slide_02.jpg, slide_03.jpg, slide_04.jpg, slide_05.jpg, slide_06.jpg | V4: Ready | Z4: Evergreen
A5: 4 | B5: 46303 | C5: =TEXT(B5,"ddd") -> Thu | D5: 20:30 | E5: IST | F5: Single | G5: Global | H5: S35 | I5: Poll: venue first or guest list | J5: Venue first, or guest list first? | K5: The great planning debate, settled by you. Team Venue says: book the mandap or the arch you love, then build the list around its capacity. Team Guest List says: know your numbers first, or you'll fall for a place that fits half your family. Both work. Whichever you pick, the invitation comes next, and that's where Lumhe helps: one link for your invite, RSVPs and photos. Comment V or G, and share this with whoever you're planning with. | L5: #Lumhe #WeddingPoll #WeddingVenue #GuestList #WeddingDebate #EngagedLife #WeddingPlanningJourney #Mandap #WeddingDecor #BrideAndGroomToBe #CelebrationPlanning | M5: Our vote: guest list first. Fight us gently in the replies. | N5: Watercolour of an empty mandap framed by a floral arch. Text asks 'Venue first, or guest list first?' and invites comments. | O5: Cast your vote | P5: 1 image · 4:5 | R5: US-21 | S5: Wedding Invitation Templates | T5: Posts/004_2026-10-08_Single_S35_Poll-venue-first-or-guest-list | U5: post.jpg | V5: Ready | Z5: Blog image
A6: 5 | B6: 46304 | C6: =TEXT(B6,"ddd") -> Fri | D6: 12:30 | E6: IST | F6: Reel | G6: India | H6: E21 | I6: NRI family plans a Pune wedding | J6: Shaadi in Pune. Family in Toronto. | K6: No hour is a good hour to call home before the shaadi. If you're planning a wedding in Pune, Jaipur or Kochi from Toronto, Dubai or London, you know the drill: late-night calls, 6 a.m. voice notes, and three relatives each holding a different version of the guest list. What actually helps: • One standing family call a week, at an hour both sides can manage • One guest list everyone works from, not five forwarded PDFs • RSVPs collected per function, so you know who's coming to Haldi and who's only coming to the Reception That's the job Lumhe does. Upload your card, add each function, and share one link on WhatsApp. Guests reply without an app or login, and you see live headcounts from wherever you are. Send this to the cousin abroad who's secretly running the wedding. Create your event free, link in bio. | L6: #Lumhe #NRIWedding #NRIWeddingPlanning #DestinationWeddingIndia #IndianWeddingPlanning #DesiDiaspora #WeddingFromAbroad #PuneWedding #ShaadiPlanning #WeddingRSVP #DigitalWeddingInvitation #BrotherKiShaadi | M6: Abroad or at home: which side of the family time zone are you on? | N6: Watercolour reel: a woman with chai by a snowy night window beside a marigold-draped suitcase, and a mother hanging a marigold toran in a sunny Indian courtyard. Text tells how one link coordinates a wedding in India from abroad. | O6: Create your event | P6: 15 s · 9:16 | Q6: Soft lo-fi beat with a gentle flute or sitar line that lifts into an upbeat dhol groove on the CTA. | R6: EV-E21_A, EV-E21_B | S6: New watercolour, blog topic: nri-wedding | New watercolour, blog topic: nri-wedding | T6: Posts/005_2026-10-09_Reel_E21_NRI-family-plans-a-Pune-wedding | U6: reel.mp4, reel_cover.jpg | V6: Ready | Z6: Evergreen
A7: 6 | B7: 46304 | C7: =TEXT(B7,"ddd") -> Fri | D7: 21:30 | E7: 19:30 IST = 9:00 AM ET · 21:30 IST = 11:00 AM ET | F7: Single | G7: USA | H7: E27 | I7: Whose name goes first | J7: Whoever hosts decides whose name goes first | K7: Two names, one order, and somehow a whole family debate. Here's the traditional rule: when the bride's parents host, the bride's name comes first. When the groom's family hosts, his name can lead. When you host together, or as two brides or two grooms, any order works, alphabetical included. The real rule? Consistency. Same order on the invite, the envelope, the wedding website and the RSVP page. On Lumhe, your names, invite and RSVP live on one link, so they always match. Save this for wording day. | L7: #Lumhe #WeddingEtiquette #WeddingInvitationWording #WeddingInvites #EngagedLife #BrideToBe #GroomToBe #WeddingPlanningTips #ModernWedding #WeddingStationery #DigitalInvitations | M7: Whose name went first on yours, and who won that argument? | N7: Watercolor of a calligrapher's desk with a blank ivory invitation, fountain pen, ink pot, eucalyptus and marigold petals. Text reads 'Whoever hosts decides whose name goes first' with a short etiquette rule. | O7: Word your invite | P7: 1 image · 4:5 | R7: EV-E27_A | S7: New watercolour, blog topic: whose-name-first | T7: Posts/006_2026-10-09_Single_E27_Whose-name-goes-first | U7: post.jpg | V7: Ready | Z7: Evergreen
A8: 7 | B8: 46305 | C8: =TEXT(B8,"ddd") -> Sat | D8: 12:30 | E8: IST | F8: Reel | G8: India | H8: F02 | I8: Navratri eve invite reminder reel | J8: Garba starts tomorrow. Invite sent? | K8: Kalash tomorrow, Garba tomorrow night, guest list still a vibe. 😅 If you're hosting a Garba night, a society Dandiya or Kanya Pujan this Navratri, tonight is the night to send the invite. Not a blurry forward that sinks under good-morning messages, but one link with the date, time, venue and the colour of the day. On Lumhe, add each night as a function. Guests tap, RSVP for the nights they're coming, and you see the headcount live, so you know exactly how many dandiya sticks and how much nimbu-paani you need. Afterwards, everyone's videos go into one Moments album, in full quality. Share this with the friend hosting this year. Make your invite free, link in bio. | L8: #Lumhe #NavratriTomorrow #Garba2026 #DandiyaRaas #NavratriReels #GarbaLovers #Navratri #GujaratiGarba #NavratriPreparations #FestiveReels #DigitalInvite | M8: Which colour are you wearing on day one? Drop it below. | N8: Watercolour reel: a couple mid-Garba with dandiya sticks beside a glowing garbo pot, and a puja thali with a diya, chunri-wrapped coconut and dandiya sticks. Text urges hosts to send their Navratri invite tonight. | O8: Make your invite | P8: 15 s · 9:16 | Q8: Upbeat dhol-and-dandiya folk fusion with a fast build, clapping on every scene change. | R8: PAIR-NAV_A, PAIR-NAV_B | S8: New watercolour, blog topic: festival | New watercolour, blog topic: festival | T8: Posts/007_2026-10-10_Reel_F02_Navratri-eve-invite-reminder-reel | U8: reel.mp4, reel_cover.jpg | V8: Ready | X8: Sharad Navratri | Y8: 2026-10-11 | Z8: Reminder (1-2 days) | AA8: F01
A9: 8 | B9: 46305 | C9: =TEXT(B9,"ddd") -> Sat | D9: 19:00 | E9: IST | F9: Carousel | G9: India | H9: F04 | I9: Dussehra get-together planning guide | J9: Ravan Dahan plans, sorted before the arrows fly | K9: The jalebi queue is already forming in our heads. 🏹 Dussehra is the day the whole family wants to be together: lunch at home, an evening at the Ramlila ground, and the cheer when the Ravan effigy goes up in flames. It all goes better when everyone knows the plan. Swipe for: • Invite wording for a family Dussehra lunch • What to tell guests for a colony Ravan Dahan • The shami leaf 'sona' line for Marathi homes • A host checklist to book now Put the whole day in one Lumhe link, with an RSVP for each part, and keep every effigy-burning video in one Moments album instead of ten family chats. Save this for your planning group. Create your invite free, link in bio. | L9: #Lumhe #Dussehra2026 #Vijayadashami #RavanDahan #Ramlila #DussehraCelebration #ShamiPuja #JalebiFafda #FestiveSeasonIndia #GoodOverEvil #DussehraVibes #FamilyGetTogether | M9: Ramlila ground or home lunch: where does your family spend Dussehra? | N9: Watercolour carousel: a family watching a tall Ravan effigy at dusk, and a brass plate of shami leaves with a small bow and arrow and jalebis. Slides share Dussehra invite wording and a host checklist. | O9: Plan your Dussehra | P9: 6 slides | R9: PAIR-DUS_A, PAIR-DUS_B | S9: New watercolour, blog topic: festival | New watercolour, blog topic: festival | T9: Posts/008_2026-10-10_Carousel_F04_Dussehra-get-together-planning-guide | U9: slide_01.jpg, slide_02.jpg, slide_03.jpg, slide_04.jpg, slide_05.jpg, slide_06.jpg | V9: Ready | X9: Dussehra | Y9: 2026-10-20 | Z9: 10 days before | AA9: F05
A10: 9 | B10: 46306 | C10: =TEXT(B10,"ddd") -> Sun | D10: 12:30 | E10: IST | F10: Single | G10: India | H10: F03 | I10: Navratri day one greeting | J10: Nine nights of shakti, devotion and dancing feet | K10: Jai Mata Di! 🌼 Today the kalash is placed, the diya is lit and nine nights of Garba, fasting and family begin. May Maa Durga fill your home with strength, peace and plenty, and may your feet never tire before the last round of Garba. Shubh Navratri from all of us at Lumhe. Hosting Kanya Pujan or a Garba night this week? Your invite is ready in minutes at lumhe.com. | L10: #Lumhe #ShubhNavratri #HappyNavratri #JaiMataDi #NavratriWishes #Ghatasthapana #MaaDurga #NavratriGreetings #NavratriDay1 #Shakti #FestivalsOfIndia | M10: Which day of Navratri do you look forward to most? Tell us why. | N10: Watercolour of a red chunri-draped kalash with mango leaves and a coconut, a pot of sprouting barley, a glowing diya and marigold garlands. Text reads 'Shubh Navratri: Nine nights of shakti, devotion and dancing feet.' | O10: Send the wish | P10: 1 image · 4:5 | R10: DAY-NAV_A | S10: New watercolour, blog topic: festival | T10: Posts/009_2026-10-11_Single_F03_Navratri-day-one-greeting | U10: post.jpg | V10: Ready | X10: Sharad Navratri | Y10: 2026-10-11 | Z10: On the day
A11: 10 | B11: 46306 | C11: =TEXT(B11,"ddd") -> Sun | D11: 21:30 | E11: 19:30 IST = 9:00 AM ET · 21:30 IST = 11:00 AM ET | F11: Carousel | G11: USA | H11: E28 | I11: Destination wedding invite timing and details | J11: Your invite is also a travel brief | K11: Your guests aren't just saving a Saturday. They're booking flights. A destination wedding invitation has two jobs: make people feel wanted, and give them everything they need to plan a trip. Miss the second part and your inbox fills with "Which airport?" and "Is there a room block?" Swipe for: • When to send the save-the-date and invitation • Wording that's warm without sounding like a travel ad • The details guests need before they book • A gentle way to be clear about costs Tip: give travel dates, not just the ceremony date, so guests can plan the whole trip. Save this for your planning folder. Then put the invite, travel details and RSVP on one Lumhe link. Create yours free at lumhe.com. | L11: #Lumhe #DestinationWedding #DestinationWeddingInvitations #BeachWedding #WeddingAbroad #WeddingTimeline #SaveTheDate #WeddingPlanning2027 #TravelWedding #WeddingGuestTips #EngagedAndPlanning #WeddingRSVP | M11: Beach, mountains or a European old town: where would your dream destination wedding be? | N11: Watercolor carousel: a couple walking barefoot toward a flower-draped beach arch at golden hour, and a close-up of a passport, map, straw hat, shells and a wax-sealed envelope. Slides cover destination wedding invitation timing, wording and details. | O11: Send your invite | P11: 6 slides | R11: EV-E28_A, EV-E28_B | S11: New watercolour, blog topic: destination-wedding | New watercolour, blog topic: destination-wedding | T11: Posts/010_2026-10-11_Carousel_E28_Destination-wedding-invite-timing-and-de | U11: slide_01.jpg, slide_02.jpg, slide_03.jpg, slide_04.jpg, slide_05.jpg, slide_06.jpg | V11: Ready | Z11: Evergreen
A12: 11 | B12: 46307 | C12: =TEXT(B12,"ddd") -> Mon | D12: 16:30 | E12: 16:30 IST = 11:00 AM UK · 23:00 IST = 5:30 PM UK | F12: Single | G12: UK | H12: E45 | I12: Gender reveal invite: keep the secret | J12: Only the baker knows. Say so on the invite. | K12: The secret is the whole party, so guard it on the invite. Tell guests who's in on it (usually just the baker or one trusted friend) and roughly when the big moment happens, so nobody nips out to feed the meter and misses it. Then cover the basics: date, time, venue with full address, parking, dress code and an RSVP date. A colour theme is half the fun: ask guests to wear pink or blue to cast their vote. On Lumhe, upload your invite, share one link in the family WhatsApp and watch the headcount build. No app, no login. Save this for your reveal, and make your invite free at lumhe.com. | L12: #Lumhe #GenderReveal #GenderRevealParty #BabyOnTheWay #UKMums #PregnancyUK #BabyShowerUK #PartyInvitations #DigitalInvitations #TeamPinkOrBlue #RevealParty #NewParentsUK | M12: Team pink, team blue or team 'just tell us already'? | N12: Watercolour of an English garden party table with a tall white cake, pink and blue balloons and marigolds. Text reads: Only the baker knows. Say so on the invite. | O12: Create your invite free | P12: 1 image · 4:5 | R12: EV-E45_A | S12: New watercolour, blog topic: gender-reveal | T12: Posts/011_2026-10-12_Single_E45_Gender-reveal-invite-keep-the-secret | U12: post.jpg | V12: Ready | Z12: Evergreen
A13: 12 | B13: 46307 | C13: =TEXT(B13,"ddd") -> Mon | D13: 20:30 | E13: IST | F13: Single | G13: Global | H13: E57 | I13: Moments: the photos on guests' phones | J13: The best photos are on their phones | K13: Your photographer got the portraits. Your guests got everything else. The cousin who caught the cake wobble. The friend who filmed the speeches. The 2 a.m. dance-floor blur that somehow sums up the whole night. Those photos usually stay stuck on a dozen different phones, or get squashed in a chat until nobody can find them. Moments collects them in one shared album: guests open your Lumhe link, tap upload and add their shots, no app and no login. It doesn't vanish after 24 hours and it isn't compressed. Start your album free at lumhe.com (link in bio). | L13: #Lumhe #EventPhotos #PhotoSharing #WeddingPhotos #GuestPhotos #PartyMemories #CelebrationPlatform #SharedAlbum #CandidMoments #WeddingGuests #PhotoAlbum | M13: Whose camera roll has the best photos from your last party? | N13: Watercolor of a reception table after the party, scattered with cameras, loose snapshots and marigolds under fairy lights. Text reads: The best photos are on their phones. | O13: Start your album | P13: 1 image · 4:5 | R13: EV-E57_A | S13: New watercolour, blog topic: share-event-photos | T13: Posts/012_2026-10-12_Single_E57_Moments-the-photos-on-guests-phones | U13: post.jpg | V13: Ready | Z13: Evergreen
A14: 13 | B14: 46308 | C14: =TEXT(B14,"ddd") -> Tue | D14: 12:30 | E14: IST | F14: Single | G14: India | H14: E04 | I14: Kannada lagna patrike structure tip | J14: Four parts every lagna patrike needs | K14: Tambula on the plate, patrike in hand, and Ajji checking the order. A Kannada lagna patrike follows a set sequence: an invocation at the top, both families' names, the muhurta with date and venue, and a closing request. A line many families use: "Taavu sakutumba sametaraagi aagamisi vadhuvararannu aashirvadisabekaagi vinanti." (We request you to come with your family and bless the couple.) Inviting friends who don't read Kannada? Add one English line under each section. Then upload the card to Lumhe and share a single link on WhatsApp. Link in bio. | L14: #Lumhe #KannadaWedding #LagnaPatrike #MaduveInvitation #KannadaMaduve #BengaluruWeddings #MysuruWeddings #KarnatakaWedding #VivahaNimantrana #WeddingCardTips #SouthIndianBride #KannadaCulture | M14: Do you still hand-deliver the patrike with tambula, or is WhatsApp fine now? | N14: Watercolour of a wedding card on a silver plate with betel leaves, areca nuts, a coconut and kumkum, framed by banana stems and a mango-leaf toran with marigolds. Text: 'Four parts every lagna patrike needs'. | O14: Upload your patrike | P14: 1 image · 4:5 | R14: EV-E04_A | S14: New watercolour, blog topic: kannada | T14: Posts/013_2026-10-13_Single_E04_Kannada-lagna-patrike-structure-tip | U14: post.jpg | V14: Ready | Z14: Evergreen
A15: 14 | B15: 46308 | C15: =TEXT(B15,"ddd") -> Tue | D15: 23:00 | E15: 16:30 IST = 11:00 AM UK · 23:00 IST = 5:30 PM UK | F15: Carousel | G15: UK | H15: E44 | I15: Hen party invitations: wording and plan | J15: From Prosecco brunch to a Brighton weekend | K15: Maid of honour duty, day one: the invitation. Get it right and the rest of the hen do plans itself. Get it wrong and you'll spend six weeks answering 'wait, which weekend?' in the group chat. Swipe for two wording styles (classy and cheeky), the four things every hen needs before saying yes, and why a weekend away needs at least two months' notice. Our favourite tip: be upfront about the rough cost per head and the deposit date. Nobody likes a surprise bill, and clear numbers mean faster replies. With Lumhe, upload the invite you designed, share one link with the hens and see exactly who's confirmed. After the weekend, everyone drops their photos into one Moments album instead of forty separate chats. Save this for when you're chief hen, tag your maid of honour, and start free at lumhe.com. | L15: #Lumhe #HenParty #HenDo #HenWeekend #BrideTribe #MaidOfHonour #HenPartyIdeas #UKBride #BrideToBe2027 #HenDoInvites #WeddingPlanningUK #Bridesmaids | M15: Spa day, city weekend or a countryside cottage: what's your dream hen? | N15: Watercolour carousel: friends clinking Prosecco glasses at a brunch table with flower crowns and marigolds, and a packed weekend bag. Cover text reads: From Prosecco brunch to a Brighton weekend. | O15: Send your hen invite | P15: 6 slides | R15: EV-E44_A, EV-E44_B | S15: New watercolour, blog topic: hen-party | New watercolour, blog topic: hen-party | T15: Posts/014_2026-10-13_Carousel_E44_Hen-party-invitations-wording-and-plan | U15: slide_01.jpg, slide_02.jpg, slide_03.jpg, slide_04.jpg, slide_05.jpg, slide_06.jpg | V15: Ready | Z15: Evergreen
A16: 15 | B16: 46309 | C16: =TEXT(B16,"ddd") -> Wed | D16: 13:00 | E16: IST | F16: Carousel | G16: Global | H16: E55 | I16: What is a celebration platform? | J16: What is a celebration platform, exactly? | K16: Invites, RSVPs, photos and gifts usually live in four different places. A celebration platform puts them on one link, so the host isn't stitching together a chat, a spreadsheet, a photo dump and an envelope box. Here's how it works on Lumhe: 1. Upload any invite you've made (Canva, PDF, image or video) or design one. 2. Add your functions, so each guest sees only the ones they're invited to. 3. Guests RSVP without downloading anything, and you see a live headcount per function. 4. After the event, everyone adds photos to Moments, a shared album that doesn't expire. In India, guests can also send shagun through Digital Lifafa, straight to your UPI ID. Swipe through, then try it free at lumhe.com. Link in bio. | L16: #Lumhe #CelebrationPlatform #DigitalInvitations #OnlineRSVP #EventPlanning #PartyPlanning #SharedPhotoAlbum #EventTech #WeddingPlanning #BirthdayPlanning #GuestList #InviteOnline | M16: Which part of hosting do you find hardest: invites, RSVPs, photos or gifts? | N16: Watercolor of a celebration table with a ribbon-tied invitation, a stack of instant photos, a gift envelope and a brass bowl of marigolds around a candle. Cover text reads: What is a celebration platform, exactly? | O16: Start celebrating free | P16: 6 slides | R16: EV-E55_A | S16: New watercolour, blog topic: celebration-platform | T16: Posts/015_2026-10-14_Carousel_E55_What-is-a-celebration-platform | U16: slide_01.jpg, slide_02.jpg, slide_03.jpg, slide_04.jpg, slide_05.jpg, slide_06.jpg | V16: Ready | Z16: Evergreen
A17: 16 | B17: 46309 | C17: =TEXT(B17,"ddd") -> Wed | D17: 21:30 | E17: 19:30 IST = 9:00 AM ET · 21:30 IST = 11:00 AM ET | F17: Single | G17: USA | H17: S32 | I17: Fall wedding invite dress code tip | J17: Let your invite set the dress code | K17: Golden leaves, crisp air and one guest question: what do I wear? Your fall wedding invitation is the first preview of the day, so let it set the formality before anyone goes shopping. Try lines like: "Cocktail attire. The evening gets crisp, so bring a wrap." "Rustic chic: boots welcome, heels may sink in the orchard." Pick colors from the season too: burgundy, burnt orange, sage and gold read "fall" instantly. Building your own invite? Upload it to Lumhe and share one link with RSVP built in. Link in bio. 🍂 | L17: #Lumhe #FallWedding #AutumnWedding #FallWeddingInvitations #WeddingDressCode #OctoberBride #RusticWedding #WeddingInvitationIdeas #BrideToBe #DigitalInvitations #WeddingPlanningTips #BurgundyWedding | M17: Fall couples: cocktail attire, black-tie or boots-and-flannel? Tell us your dress code. | N17: Watercolor illustration of a bride holding a bouquet among autumn trees with golden leaves. Text reads: Fall wedding tip, Let your invite set the dress code. | O17: Create your invite free | P17: 1 image · 4:5 | R17: US-16 | S17: Create Your Own Wedding Invitations: Complete Guide | T17: Posts/016_2026-10-14_Single_S32_Fall-wedding-invite-dress-code-tip | U17: post.jpg | V17: Ready | Z17: Blog image
A18: 17 | B18: 46310 | C18: =TEXT(B18,"ddd") -> Thu | D18: 19:30 | E18: 19:30 IST = 9:00 AM ET · 21:30 IST = 11:00 AM ET | F18: Carousel | G18: USA | H18: C24 | I18: Invite platform comparison checklist | J18: Evite, Paperless Post or Lumhe? Compare this | K18: The prettiest template isn't always the best invite platform. Evite and Paperless Post are both well-known names for digital invitations, and each has its fans. Before you commit, run your shortlist through five quick questions: 1. Can guests RSVP without making an account? 2. Can you upload the design you already have? 3. Does it handle multiple events, like a welcome dinner, ceremony and brunch? 4. Is there somewhere for guests to share photos afterward? 5. What's free, and what costs extra? Whichever platform you pick, these answers decide whether your guests actually reply, and whether you spend RSVP week chasing people by text. Lumhe is our answer: bring any design, share one link, track RSVPs per event and collect every guest's photos in one Moments album. Free to start at the link in bio. Save this before you choose. | L18: #Lumhe #DigitalInvitations #OnlineInvitations #EInvite #WeddingPlanningTips #RSVP #EventPlanningTips #PartyPlanning #WeddingTech #BrideToBe2027 #PaperlessWedding #InvitationIdeas #HostingTips | M18: Which matters most to you: design, RSVP tracking or price? | N18: Watercolour illustration of a hand holding a phone with a gold invitation against navy tones. Text reads: Evite, Paperless Post or Lumhe? Compare this. | O18: Try Lumhe free | P18: 6 slides | R18: US-15, UK-21 | S18: Wedding Invitations Cheap | Personalised Party Invites: Complete Guide | T18: Posts/017_2026-10-15_Carousel_C24_Invite-platform-comparison-checklist | U18: slide_01.jpg, slide_02.jpg, slide_03.jpg, slide_04.jpg, slide_05.jpg, slide_06.jpg | V18: Ready | Z18: Blog image
A19: 18 | B19: 46310 | C19: =TEXT(B19,"ddd") -> Thu | D19: 21:30 | E19: 19:30 IST = 9:00 AM ET · 21:30 IST = 11:00 AM ET | F19: Single | G19: USA | H19: E29 | I19: Rehearsal dinner invite tip | J19: The night before the vows deserves its own invite | K19: Toasts, stories and the first time both families share a table. A rehearsal dinner invite should say three things clearly: who it's for, where to go right after the rehearsal, and whether plus-ones and kids are included. Traditionally the groom's family hosts, but today anyone can. Wording to borrow: "Before we say I do, let's raise a glass. Join us for dinner after the rehearsal, Friday at 7 p.m." Make it on Lumhe, send one link and watch the RSVPs come in. Create yours free, link in bio. | L19: #Lumhe #RehearsalDinner #RehearsalDinnerInvite #WeddingWeekend #WeddingParty #WeddingEve #WeddingInvitationIdeas #BrideAndGroom #WeddingToasts #IntimateDinner #OnlineRSVP | M19: Rehearsal dinner: cozy family meal or the wedding weekend's real party? | N19: Watercolor of a candlelit restaurant table set for a rehearsal dinner with roses, marigolds and string lights. Text reads 'The night before the vows deserves its own invite' with a timing tip. | O19: Create your invite | P19: 1 image · 4:5 | R19: EV-E29_A | S19: New watercolour, blog topic: rehearsal-dinner | T19: Posts/018_2026-10-15_Single_E29_Rehearsal-dinner-invite-tip | U19: post.jpg | V19: Ready | Z19: Evergreen
A20: 19 | B20: 46311 | C20: =TEXT(B20,"ddd") -> Fri | D20: 12:30 | E20: IST | F20: Carousel | G20: India | H20: E02 | I20: Tamil kalyana pathirikai wording and design | J20: Tamil wedding wording, start to finish | K20: Jasmine, temple gold and a card that starts with one small symbol. A Tamil kalyana pathirikai has a rhythm families know by heart. The Pillaiyar Suzhi (உ) sits at the top, both families are named with respect, the muhurtham is stated clearly, and the closing asks guests to come with their kin and bless the couple. Swipe for: • What goes first on the card • A Tamil closing line, with meaning • An English line for friends • Design cues that feel traditional, not dated Tip: put the reception on its own line, since many friends only come for that evening. Save this for your card meeting. Then upload the final pathirikai to Lumhe and share one link with an RSVP for the muhurtham and reception. Link in bio. | L20: #Lumhe #TamilWedding #KalyanaPathirikai #TamilWeddingCard #ChennaiWeddings #Muhurtham #TamilBride #KanjeevaramBride #SouthIndianWeddings #ThirumanaAzhaippithazh #WeddingCardDesign #MaduraiWeddings | M20: Team traditional yellow-and-maroon card or team pastel? Vote below. | N20: Watercolour of a Tamil bride in a Kanjeevaram silk saree with temple jewellery and a jasmine-strand plait, beside banana trees and marigold garlands. Slides give Tamil wedding invitation wording and design tips. | O20: Upload your pathirikai | P20: 6 slides | R20: EV-E02_A | S20: New watercolour, blog topic: tamil-wedding-invitation | T20: Posts/019_2026-10-16_Carousel_E02_Tamil-kalyana-pathirikai-wording-and-des | U20: slide_01.jpg, slide_02.jpg, slide_03.jpg, slide_04.jpg, slide_05.jpg, slide_06.jpg | V20: Ready | Z20: Evergreen
A21: 20 | B21: 46311 | C21: =TEXT(B21,"ddd") -> Fri | D21: 23:00 | E21: 16:30 IST = 11:00 AM UK · 23:00 IST = 5:30 PM UK | F21: Single | G21: UK | H21: E46 | I21: 60th birthday invite wording | J21: Sixty years young and still first on the dance floor. Join us for afternoon tea and bubbles. | K21: Turning sixty deserves better than a 'drinks at ours?' text. Whether it's a garden party with Pimm's and croquet or a proper afternoon tea with scones and fine china, the invite sets the tone. Keep it warm, a little cheeky and crystal clear on the practical bits: date, start and finish time, address, dress code and an RSVP date. Scones before or after the speeches? Add a rough timeline so Grandad knows when to stand up. Copy the wording above, then make your invite on Lumhe and track replies in one place, free. Who's turning sixty in your family? Tag the person organising it. | L21: #Lumhe #60thBirthday #SixtyAndFabulous #60thBirthdayParty #BirthdayInvitations #GardenParty #AfternoonTea #MilestoneBirthday #UKParty #PartyPlanningUK #BirthdayIdeas | M21: Garden party or afternoon tea: how would you celebrate sixty? | N21: Watercolour of an English garden afternoon tea with a tiered stand, fine china and marigolds under string lights. Text reads: Sixty years young and still first on the dance floor. Join us for afternoon tea and bubbles. | O21: Make your invite free | P21: 1 image · 4:5 | R21: EV-E46_A | S21: New watercolour, blog topic: 60th-birthday | T21: Posts/020_2026-10-16_Single_E46_60th-birthday-invite-wording | U21: post.jpg | V21: Ready | Z21: Evergreen
A22: 21 | B22: 46312 | C22: =TEXT(B22,"ddd") -> Sat | D22: 19:30 | E22: 19:30 IST = 9:00 AM ET · 21:30 IST = 11:00 AM ET | F22: Reel | G22: USA | H22: E34 | I22: Themed party invites that set the tone | J22: The theme starts at the invite | K22: Guests decide how excited to be the moment they open the invite. A themed invitation does half your hosting for you. It tells kids what to wear, tells parents what to expect, and gets everyone talking before the party even starts. A few lines to borrow: 🦖 Dinosaurs: "Stomp on over! Max is turning five." ☕ Tea party: "You're invited to a tea-riffic afternoon. Hats encouraged." 🏖️ Beach: "Sunscreen on, flip-flops ready. We're throwing a splash party." Add the essentials too: date, time, address, what to wear and an RSVP date. On Lumhe you can upload your themed design or make one, send a single link, and watch the headcount update live. Create your party invite free at lumhe.com. | L22: #Lumhe #ThemedParty #PartyInvitations #KidsBirthdayParty #DinosaurParty #TeaPartyIdeas #BeachParty #BirthdayPartyIdeas #PartyPlanningMom #KidsPartyIdeas #DigitalInvites #OnlineRSVP #PartyInspo | M22: What's the best party theme you've ever been invited to? | N22: Watercolor reel: children in dinosaur costumes beside a dinosaur cake and balloons in a backyard, and a close-up of a tea-party table with floral cups and macarons. Text shares themed invitation wording ideas. | O22: Make your invite | P22: 15 s · 9:16 | Q22: Bright, bouncy ukulele-pop track with handclaps; quick cuts on each beat. | R22: EV-E34_A, EV-E34_B | S22: New watercolour, blog topic: themed-party | New watercolour, blog topic: themed-party | T22: Posts/021_2026-10-17_Reel_E34_Themed-party-invites-that-set-the-tone | U22: reel.mp4, reel_cover.jpg | V22: Ready | Z22: Evergreen
A23: 22 | B23: 46312 | C23: =TEXT(B23,"ddd") -> Sat | D23: 20:30 | E23: IST | F23: Single | G23: Global | H23: E58 | I23: Free invitation maker: what to check | J23: Free to design isn't always free to send | K23: Before you fall for a template, read what 'free' actually covers. Some tools let you design for free but charge when you send. Others cap the number of guests or keep RSVPs behind an upgrade. And some ask every guest to download an app first, which is where replies go to die. A quick checklist before you commit: • Can you send to your whole list at no cost? • Do RSVPs come back in one place? • Can guests open it without signing up? • Can you bring a design you already made? Lumhe does all four, free. Bring your Canva file, PDF or video, or design one, and share a single link. Try it at lumhe.com. | L23: #Lumhe #FreeInvitations #InvitationMaker #OnlineInvitations #DigitalInvite #FreeTemplates #PartyInvites #EventInvites #DIYInvitations #RSVPOnline #InviteDesign | M23: What's the most annoying 'free' catch you've run into? | N23: Watercolor of a tidy desk with sketched invitation layouts, sample cards, colored pencils, tea and marigolds. Text reads: Free to design isn't always free to send. | O23: Try Lumhe free | P23: 1 image · 4:5 | R23: EV-E58_A | S23: New watercolour, blog topic: free-invitation-maker | T23: Posts/022_2026-10-17_Single_E58_Free-invitation-maker-what-to-check | U23: post.jpg | V23: Ready | Z23: Evergreen
A24: 23 | B24: 46313 | C24: =TEXT(B24,"ddd") -> Sun | D24: 12:30 | E24: IST | F24: Single | G24: India | H24: E07 | I24: Christian wedding invite: church and reception | J24: Church at 11. Reception at 7. Separate RSVPs. | K24: White lilies, a church bell, and a caterer asking for numbers. Many Christian weddings in India have two parts: the Holy Matrimony at church and a reception later. A wording line families use: "Together with their families, Anita and Joel request the honour of your presence at their Holy Matrimony at St. Thomas Church, followed by a reception." Some add a verse at the top, such as 1 Corinthians 13:4, "Love is patient, love is kind." On Lumhe, guests RSVP to each part separately, so the reception count is real. Create your invite at lumhe.com. | L24: #Lumhe #ChristianWedding #ChristianWeddingIndia #HolyMatrimony #ChurchWedding #KeralaChristianWedding #GoanWedding #WeddingReception #WhiteSareeBride #WeddingInvitationIndia #ChristianBride #WeddingRSVP | M24: Which verse would you put on your card? Share it below. | N24: Watercolour of an Indian Christian bride in a white saree and veil with the groom in a suit outside a whitewashed church, with white lilies and marigold garlands. Text reads: church at 11, reception at 7, separate RSVPs. | O24: Create your invite | P24: 1 image · 4:5 | R24: EV-E07_A | S24: New watercolour, blog topic: christian-wedding | T24: Posts/023_2026-10-18_Single_E07_Christian-wedding-invite-church-and-rece | U24: post.jpg | V24: Ready | Z24: Evergreen
A25: 24 | B25: 46313 | C25: =TEXT(B25,"ddd") -> Sun | D25: 21:30 | E25: 19:30 IST = 9:00 AM ET · 21:30 IST = 11:00 AM ET | F25: Carousel | G25: USA | H25: E30 | I25: Christmas-season wedding invitations | J25: Saying I do when it snows | K25: A December wedding competes with every office party in town. Winter weddings are cozy, candlelit and full of twinkle, but your guests' calendars are packed and holiday travel books up early. The invite has to land first and answer more questions than usual. Swipe for: • When to send for a December date • A formal wording sample with a seasonal touch • A playful option for a relaxed celebration • The winter details guests always ask about Tip: name the holiday-week hotel rate on your details page. Guests notice it. Save this if you're saying "I do" in the snow. Then share your invite, details and RSVP on one Lumhe link. Create yours free at lumhe.com. | L25: #Lumhe #ChristmasWedding #WinterWedding #DecemberWedding #HolidayWedding #WinterWeddingInvitations #SnowyWedding #WeddingInvitationWording #FestiveWedding #WeddingSeason #EngagedAF #WeddingDetails | M25: Winter wedding: velvet and candlelight, or would you rather wait for summer? | N25: Watercolor carousel: a couple under an evergreen arch with red berries, pine garlands and candle lanterns in light snow outside a barn. Slides share timing, wording and guest details for Christmas-season wedding invitations. | O25: Create your invite | P25: 6 slides | R25: EV-E30_A | S25: New watercolour, blog topic: christmas-wedding-invitations | T25: Posts/024_2026-10-18_Carousel_E30_Christmas-season-wedding-invitations | U25: slide_01.jpg, slide_02.jpg, slide_03.jpg, slide_04.jpg, slide_05.jpg, slide_06.jpg | V25: Ready | Z25: Evergreen
A26: 25 | B26: 46314 | C26: =TEXT(B26,"ddd") -> Mon | D26: 12:30 | E26: IST | F26: Single | G26: India | H26: F05 | I26: Dussehra eve meet-up reminder | J26: Ravan burns tomorrow. Does everyone know where to meet? | K26: Tomorrow evening, half the colony will be at the Ramlila ground. And nobody will find anybody. Fix that tonight. Send the family one link with lunch timings, the ground's location pin and a clear meet-up spot for after the Ravan Dahan (the jalebi stall counts). Ask for a quick RSVP so you know how many plates to plan. On Lumhe, it takes a few minutes and opens straight from WhatsApp, no app needed. Make yours free, link in bio. | L26: #Lumhe #DussehraTomorrow #Dussehra #RavanDahan2026 #Vijayadashami2026 #RamlilaNights #DussehraPlans #FestivalReminder #IndianFestivals #FamilyPlans #DigitalInvitation | M26: Who in your family always gets lost at the Ravan Dahan? Tag them 😄 | N26: Watercolour of a family seen from behind watching a tall Ravan effigy at dusk, a child on her father's shoulders. Text reads 'Ravan burns tomorrow. Does everyone know where to meet?' | O26: Send one link | P26: 1 image · 4:5 | R26: PAIR-DUS_A, PAIR-DUS_B | S26: New watercolour, blog topic: festival | New watercolour, blog topic: festival | T26: Posts/025_2026-10-19_Single_F05_Dussehra-eve-meet-up-reminder | U26: post.jpg | V26: Ready | X26: Dussehra | Y26: 2026-10-20 | Z26: Reminder (1-2 days) | AA26: F04
A27: 26 | B27: 46314 | C27: =TEXT(B27,"ddd") -> Mon | D27: 19:00 | E27: IST | F27: Carousel | G27: India | H27: F07 | I27: Karva Chauth gathering planning guide | J27: From sargi to moonrise, planned with love | K27: Ten days to the most photographed moon of the year. 🌙 Karva Chauth is about the vrat, but for many of us it's also about the evening together: mehendi the night before, the katha with friends, and that rooftop wait for the moon with a sieve in hand. Swipe for: • Katha invite wording you can copy • How to host a mehendi night without chaos • The puja thali checklist • A moonrise plan, with a backup Hosting? Put both evenings in one Lumhe link, see who's coming to each, and gather every moon photo in one Moments album. Save this and send it to your Karva Chauth group. Link in bio. | L27: #Lumhe #KarvaChauth2026 #KarvaChauth #KarwaChauth #Sargi #MehendiNight #KarvaChauthThali #MoonriseRitual #FestiveFashion #PunjabiTraditions #IndianFestival #KarvaChauthSpecial | M27: Mehendi the night before or the same morning? Tell us your ritual. | N27: Watercolour carousel: a woman in a red saree raising a sieve to the moon on a rooftop beside her husband, and hennaed hands holding a puja thali with a karva, sieve and diya. Slides share Karva Chauth invite wording and a puja checklist. | O27: Plan the gathering | P27: 6 slides | R27: PAIR-KC_A, PAIR-KC_B | S27: New watercolour, blog topic: festival | New watercolour, blog topic: festival | T27: Posts/026_2026-10-19_Carousel_F07_Karva-Chauth-gathering-planning-guide | U27: slide_01.jpg, slide_02.jpg, slide_03.jpg, slide_04.jpg, slide_05.jpg, slide_06.jpg | V27: Ready | X27: Karva Chauth | Y27: 2026-10-29 | Z27: 10 days before | AA27: F08
A28: 27 | B28: 46315 | C28: =TEXT(B28,"ddd") -> Tue | D28: 12:30 | E28: IST | F28: Single | G28: India | H28: F06 | I28: Dussehra day greeting | J28: Goodness wins. Today, and every day after. | K28: Vijayadashami ki hardik shubhkamnayein! 🏹 Today we remember that truth wins, however tall the Ravan. May this Dussehra burn away whatever weighs on you and bring fresh starts, golden shami leaves and a plate of hot jalebis. To every Marathi home: Sona ghya, sonyasarkha raha! 💛 From all of us at Lumhe, Happy Dussehra. Planning the Diwali get-together next? Lumhe is ready when you are. | L28: #Lumhe #HappyDussehra #ShubhVijayadashami #DussehraWishes #VictoryOfGood #Dasara #DussehraGreetings #DasaraWishes #SonaGhya #FestiveIndia #Vijayadashami2026Wishes | M28: Leave a 🏹 if you're watching the Ravan Dahan tonight! | N28: Watercolour of a marigold-wrapped bow and arrow resting against a lit brass diya on a red and yellow rangoli, with shami leaves scattered around. Text reads 'Happy Dussehra: Goodness wins. Today, and every day after.' | O28: Share the wish | P28: 1 image · 4:5 | R28: DAY-DUS_A | S28: New watercolour, blog topic: festival | T28: Posts/027_2026-10-20_Single_F06_Dussehra-day-greeting | U28: post.jpg | V28: Ready | X28: Dussehra | Y28: 2026-10-20 | Z28: On the day
A29: 28 | B29: 46315 | C29: =TEXT(B29,"ddd") -> Tue | D29: 21:30 | E29: 19:30 IST = 9:00 AM ET · 21:30 IST = 11:00 AM ET | F29: Single | G29: USA | H29: E31 | I29: 18th birthday invite tip | J29: Eighteen: officially old enough to write the invite | K29: Eighteen is the first party they'll want to plan themselves. Hand over the theme and the wording, and keep the logistics. A good 18th invite still needs the basics: date, start and end time, address, dress code if there is one, and a clear RSVP date so you can plan food. Wording to borrow: "Eighteen, finally. Come celebrate with cake, music and way too many photos." On Lumhe they design it, you see the headcount, and everyone's photos land in one Moments album. Create it free, link in bio. | L29: #Lumhe #18thBirthday #EighteenthBirthday #18thBirthdayParty #MilestoneBirthday #BirthdayInvitations #BackyardParty #PartyPlanning #SeniorYear #BirthdayPartyIdeas #OnlineInvitations | M29: Parents of 18-year-olds: who wrote the invite in your house? | N29: Watercolor of a backyard party at dusk with a sparkler-lit cake, instant photos on twine and string lights. Text reads 'Eighteen: officially old enough to write the invite' with a tip for parents. | O29: Start the invite | P29: 1 image · 4:5 | R29: EV-E31_A | S29: New watercolour, blog topic: 18th-birthday | T29: Posts/028_2026-10-20_Single_E31_18th-birthday-invite-tip | U29: post.jpg | V29: Ready | Z29: Evergreen
A30: 29 | B30: 46316 | C30: =TEXT(B30,"ddd") -> Wed | D30: 16:30 | E30: 16:30 IST = 11:00 AM UK · 23:00 IST = 5:30 PM UK | F30: Carousel | G30: UK | H30: E48 | I30: Wedding RSVP website guide (UK) | J30: Your RSVP site has one job | K30: Sticky notes, spreadsheets and that RSVP card behind the clock. A wedding RSVP website gathers every answer in one place, but only if you ask the right questions. Swipe for what to put on the form, how to handle day and evening guests, when to set the reply-by date and how to make answering effortless. The big one for UK weddings: day guests and evening guests are really two events. Count them separately and you'll know exactly how many wedding breakfasts to order and how many bacon butties to plan for at 10pm. Lumhe lets you add both as separate functions under one link, so each guest sees only what they're invited to and you get a live headcount for each. Guests don't need an app or a login. Save this for your planning folder, share it with your other half and start free at lumhe.com. | L30: #Lumhe #WeddingRSVP #RSVPWebsite #UKWedding #WeddingPlanningUK #EveningReception #WeddingBreakfast #BrideToBeUK #Engaged2026 #WeddingGuestList #WeddingWebsite #UKBrides | M30: Day guests vs evening guests: how big is your gap? | N30: Watercolour of a cosy kitchen table with an open wedding planner, cream RSVP cards tied with twine, a teapot and marigolds. Cover text reads: Your RSVP site has one job. | O30: Track RSVPs free | P30: 6 slides | R30: EV-E48_A | S30: New watercolour, blog topic: wedding-rsvp-website | T30: Posts/029_2026-10-21_Carousel_E48_Wedding-RSVP-website-guide-UK | U30: slide_01.jpg, slide_02.jpg, slide_03.jpg, slide_04.jpg, slide_05.jpg, slide_06.jpg | V30: Ready | Z30: Evergreen
A31: 30 | B31: 46316 | C31: =TEXT(B31,"ddd") -> Wed | D31: 21:30 | E31: 19:30 IST = 9:00 AM ET · 21:30 IST = 11:00 AM ET | F31: Carousel | G31: USA | H31: F10 | I31: Halloween invite wording and host plan | J31: Costumes? Kids? Answer it on the invite | K31: Two questions will flood your DMs this month. Answer them now. "Do I have to dress up?" and "Can I bring the kids?" If your Halloween invite answers both, you skip most of October's follow-up texts. Halloween falls on a Saturday this year, so party calendars will fill fast. Swipe for: • Wording for an adults-only haunted evening • Wording for a family costume party • The two lines every invite needs • A ten-day host timeline Make the invite on Lumhe or upload the one you designed, text one link, and watch the RSVPs come in. After the party, guests drop their photos into one Moments album. Save this, then send yours this week. Link in bio. 🎃 | L31: #Lumhe #Halloween2026 #HalloweenParty #HalloweenInvitations #HalloweenPartyIdeas #CostumeParty #TrickOrTreat #SpookySeason #HalloweenHost #PartyPlanning #FamilyHalloween #HauntedHouseParty #OctoberVibes | M31: Costume required or optional at your party? Cast your vote below 🎃 | N31: Watercolor carousel: pumpkins and friendly ghosts lining garden stairs, and a mantel styled with a pumpkin, ghosts and a wreath. Slides share Halloween invitation wording and a ten-day host timeline. | O31: Send your invite | P31: 6 slides | R31: US-72, US-50 | S31: Wedding Invitations Cheap: Complete Guide | Evite Invitations: Review, Features & Alternatives | T31: Posts/030_2026-10-21_Carousel_F10_Halloween-invite-wording-and-host-plan | U31: slide_01.jpg, slide_02.jpg, slide_03.jpg, slide_04.jpg, slide_05.jpg, slide_06.jpg | V31: Ready | X31: Halloween | Y31: 2026-10-31 | Z31: 10 days before | AA31: R02
A32: 31 | B32: 46317 | C32: =TEXT(B32,"ddd") -> Thu | D32: 16:30 | E32: 16:30 IST = 11:00 AM UK · 23:00 IST = 5:30 PM UK | F32: Single | G32: UK | H32: E47 | I32: Save the date: only the essentials | J32: Names, date, town. The rest can wait. | K32: The prettiest save the dates say the least. It's tempting to cram in the venue, the dress code and your entire love story. Don't. A save the date has one job: get the date into calendars before guests book their own plans. What it needs: your names, the date, the town or region, and 'Formal invitation to follow'. That's it. Pick a template that matches your season (autumn leaves, winter berries, spring blossom) and keep the wording short enough to read at a glance. Made yours already? Upload it to Lumhe and share it as one link, then send the full invitation from the same place later. Save this, and start at lumhe.com. | L32: #Lumhe #SaveTheDate #SaveTheDateUK #SaveTheDates #WeddingStationery #UKWeddings #EngagedUK #WeddingInspiration #2027Wedding #WeddingTemplates #DigitalSaveTheDate | M32: Did you send save the dates, or skip straight to invitations? | N32: Watercolour of a blank cream card propped against a vase of autumn leaves and marigolds, with a fountain pen and calendar page. Text reads: Names, date, town. The rest can wait. | O32: Send your save-the-date | P32: 1 image · 4:5 | R32: EV-E47_A | S32: New watercolour, blog topic: save-the-date-templates | T32: Posts/031_2026-10-22_Single_E47_Save-the-date-only-the-essentials | U32: post.jpg | V32: Ready | Z32: Evergreen
A33: 32 | B33: 46317 | C33: =TEXT(B33,"ddd") -> Thu | D33: 20:30 | E33: IST | F33: Carousel | G33: Global | H33: E59 | I33: Online wedding RSVP: per-function guide | J33: Five functions. Five different guest lists. | K33: Your caterer wants a number. Your inbox has twelve maybes. Online RSVP fixes that, especially for weddings with more than one function. The trick is per-function invites. Not everyone is invited to every event, and a single 'yes' to 'the wedding' tells you nothing about how many plates the Sangeet needs. Swipe for how it works, how to set up guest groups before you hit send and what to do about the people who never reply. On Lumhe, each guest sees only their functions and taps attending or not for each one. You get a live headcount per function, and guests don't need to download anything or log in. Save this for your wedding planning, share it with whoever is handling the guest list, and try it free at lumhe.com. | L33: #Lumhe #OnlineRSVP #WeddingRSVP #RSVPTracking #IndianWedding #MultiDayWedding #DestinationWedding #WeddingGuestList #WeddingFunctions #WeddingPlanner #SangeetNight #DigitalWedding | M33: How many functions is your wedding: two, five or 'don't ask'? | N33: Watercolour of a mother at a carved wooden table sorting invitation envelopes into neat piles marked with marigolds, roses and jasmine, beside a brass diya and chai. Cover text reads: Five functions. Five different guest lists. | O33: Set up your RSVP | P33: 6 slides | R33: EV-E59_A | S33: New watercolour, blog topic: online-rsvp | T33: Posts/032_2026-10-22_Carousel_E59_Online-wedding-RSVP-per-function-guide | U33: slide_01.jpg, slide_02.jpg, slide_03.jpg, slide_04.jpg, slide_05.jpg, slide_06.jpg | V33: Ready | Z33: Evergreen
A34: 33 | B34: 46318 | C34: =TEXT(B34,"ddd") -> Fri | D34: 12:30 | E34: IST | F34: Single | G34: India | H34: E09 | I34: Sister's wedding WhatsApp invite line | J34: Meri didi ki shaadi hai, aur aap sab ke bina adhoori lagegi. Please zaroor aaiye. | K34: Inviting people to your sister's wedding hits differently. You're not just sending details, you're asking people to show up for someone you love. Copy this for your WhatsApp invite: "मेरी दीदी की शादी है, और आप सब के बिना अधूरी लगेगी। प्लीज़ ज़रूर आइए।" For a younger sister: "Choti ki shaadi hai! Jo bachpan mein meri chocolate chura leti thi, ab dulhan banegi. Aap sab aaiye." Then share one Lumhe link with the card, venue and RSVP for every function. Link in bio. | L34: #Lumhe #SisterKiShaadi #DidiKiShaadi #SisterWedding #WeddingInvitationMessage #ShaadiInvite #WhatsAppInvite #IndianWedding #SiblingLove #BehenKiShaadi #ShaadiSeason2026 #DesiWedding | M34: Tag the sibling who'll cry first at the vidaai. | N34: Watercolour of a laughing bride in a red lehenga with marigold jewellery while her younger sister adjusts her dupatta. Text reads 'Meri didi ki shaadi hai, aur aap sab ke bina adhoori lagegi. Please zaroor aaiye.' with an English translation. | O34: Send the invite | P34: 1 image · 4:5 | R34: EV-E09_A | S34: New watercolour, blog topic: sister-marriage | T34: Posts/033_2026-10-23_Single_E09_Sister-s-wedding-WhatsApp-invite-line | U34: post.jpg | V34: Ready | Z34: Evergreen
A35: 34 | B35: 46318 | C35: =TEXT(B35,"ddd") -> Fri | D35: 23:00 | E35: 16:30 IST = 11:00 AM UK · 23:00 IST = 5:30 PM UK | F35: Reel | G35: UK | H35: E52 | I35: Kids' party invites: themes that work | J35: Dinosaurs, unicorns and twenty-two Year 2s | K35: The invite is where a calm kids' party actually begins. Dinosaurs, princesses, superheroes or unicorns: the theme is the fun part. The wording is what saves your sanity. For toddlers, keep it simple and tell parents to stay. For primary-age children, theme the language, give a clear drop-off and pick-up time, and ask about allergies on the invite itself. Add an RSVP date a few days before the party so you can sort the food, the party bags and the number of chairs without a last-minute scramble. With Lumhe, upload your themed invite, drop one link into the class WhatsApp and see who's coming as parents reply. Nobody needs an app or a login. Save this for the next birthday, and make yours free at lumhe.com. | L35: #Lumhe #KidsParty #KidsBirthdayParty #DinosaurParty #PrincessParty #PartyInvitations #UKMums #UKDads #KidsPartyIdeas #BirthdayInvites #ChildrensParty #PartyPlanningUK | M35: Dinosaur, princess, superhero or unicorn: what's this year's theme? | N35: Watercolour reel of a child's birthday table in a sunny hall with a dinosaur cake, a paper crown, a superhero cape and marigolds. Opening text reads: Dinosaurs, unicorns and twenty-two Year 2s. | O35: Make a party invite | P35: 15 s · 9:16 | Q35: Bouncy, playful ukulele-and-claps kids' party track with a cheeky drum hit on each cut. | R35: EV-E52_A | S35: New watercolour, blog topic: kids-party | T35: Posts/034_2026-10-23_Reel_E52_Kids-party-invites-themes-that-work | U35: reel.mp4, reel_cover.jpg | V35: Ready | Z35: Evergreen
